Workbook

Sheet experiment_data_clean
A1: user_id | B1: signup_date | C1: experiment_group | D1: region | E1: device_type | F1: device_type_filled_flag | G1: traffic_source | H1: traffic_source_filled_flag | I1: plan_type | J1: visited_landing_page | K1: started_trial | L1: completed_onboarding | M1: converted_to_paid | N1: invalid_binary_flag | O1: funnel_inconsistent_flag | P1: revenue_30d | Q1: revenue_logic_mismatch_flag | R1: revenue_outlier_flag | S1: support_tickets_30d | T1: has_support_ticket_flag | U1: refund_requested | V1: days_to_convert | W1: days_logic_mismatch_flag | X1: engagement_score | Y1: engagement_score_missing_flag | Z1: revenue_if_converted_helper
A2: USR-100001 | B2: 45732 | C2: Control | D2: North | E2: Desktop | F2: No | G2: Email | H2: No | I2: Basic | J2: 0 | K2: 0 | L2: 0 | M2: 0 | N2: =IF(OR(NOT(OR(J2=0,J2=1)),NOT(OR(K2=0,K2=1)),NOT(OR(L2=0,L2=1)),NOT(OR(M2=0,M2=1)),NOT(OR(U2=0,U2=1))),"Yes","No") -> No | O2: =IF(OR(AND(M2=1,L2=0),AND(L2=1,K2=0),AND(K2=1,J2=0)),"Yes","No") -> No | P2: 0 | Q2: =IF(OR(AND(M2=0,P2>0),AND(M2=1,P2<=0)),"Yes","No") -> No | R2: =IF(AND(M2=1,P2>calc_helpers!$B$5),"Yes","No") -> No | S2: 0 | T2: =IF(S2>0,"Yes","No") -> No | U2: 0 | W2: =IF(OR(AND(M2=1,ISBLANK(V2)),AND(M2=0,NOT(ISBLANK(V2)))),"Yes","No") -> No | X2: 45.7 | Y2: No | Z2: =IF(M2=1,P2,"")
A3: USR-100002 | B3: 45724 | C3: Control | D3: West | E3: Mobile | F3: No | G3: Organic | H3: No | I3: Free | J3: 1 | K3: 0 | L3: 0 | M3: 0 | N3: =IF(OR(NOT(OR(J3=0,J3=1)),NOT(OR(K3=0,K3=1)),NOT(OR(L3=0,L3=1)),NOT(OR(M3=0,M3=1)),NOT(OR(U3=0,U3=1))),"Yes","No") -> No | O3: =IF(OR(AND(M3=1,L3=0),AND(L3=1,K3=0),AND(K3=1,J3=0)),"Yes","No") -> No | P3: 0 | Q3: =IF(OR(AND(M3=0,P3>0),AND(M3=1,P3<=0)),"Yes","No") -> No | R3: =IF(AND(M3=1,P3>calc_helpers!$B$5),"Yes","No") -> No | S3: 0 | T3: =IF(S3>0,"Yes","No") -> No | U3: 0 | W3: =IF(OR(AND(M3=1,ISBLANK(V3)),AND(M3=0,NOT(ISBLANK(V3)))),"Yes","No") -> No | X3: 48.6 | Y3: No | Z3: =IF(M3=1,P3,"")
A4: USR-100003 | B4: 45771 | C4: Control | D4: East | E4: Mobile | F4: No | G4: Paid Search | H4: No | I4: Premium | J4: 1 | K4: 0 | L4: 0 | M4: 0 | N4: =IF(OR(NOT(OR(J4=0,J4=1)),NOT(OR(K4=0,K4=1)),NOT(OR(L4=0,L4=1)),NOT(OR(M4=0,M4=1)),NOT(OR(U4=0,U4=1))),"Yes","No") -> No | O4: =IF(OR(AND(M4=1,L4=0),AND(L4=1,K4=0),AND(K4=1,J4=0)),"Yes","No") -> No | P4: 0 | Q4: =IF(OR(AND(M4=0,P4>0),AND(M4=1,P4<=0)),"Yes","No") -> No | R4: =IF(AND(M4=1,P4>calc_helpers!$B$5),"Yes","No") -> No | S4: 1 | T4: =IF(S4>0,"Yes","No") -> Yes | U4: 0 | W4: =IF(OR(AND(M4=1,ISBLANK(V4)),AND(M4=0,NOT(ISBLANK(V4)))),"Yes","No") -> No | X4: 35.4 | Y4: No | Z4: =IF(M4=1,P4,"")
A5: USR-100004 | B5: 45781 | C5: Control | D5: South | E5: Mobile | F5: No | G5: Email | H5: No | I5: Basic | J5: 1 | K5: 0 | L5: 0 | M5: 0 | N5: =IF(OR(NOT(OR(J5=0,J5=1)),NOT(OR(K5=0,K5=1)),NOT(OR(L5=0,L5=1)),NOT(OR(M5=0,M5=1)),NOT(OR(U5=0,U5=1))),"Yes","No") -> No | O5: =IF(OR(AND(M5=1,L5=0),AND(L5=1,K5=0),AND(K5=1,J5=0)),"Yes","No") -> No | P5: 0 | Q5: =IF(OR(AND(M5=0,P5>0),AND(M5=1,P5<=0)),"Yes","No") -> No | R5: =IF(AND(M5=1,P5>calc_helpers!$B$5),"Yes","No") -> No | S5: 0 | T5: =IF(S5>0,"Yes","No") -> No | U5: 0 | W5: =IF(OR(AND(M5=1,ISBLANK(V5)),AND(M5=0,NOT(ISBLANK(V5)))),"Yes","No") -> No | X5: 64.6 | Y5: No | Z5: =IF(M5=1,P5,"")
A6: USR-100005 | B6: 45700 | C6: Control | D6: North | E6: Tablet | F6: No | G6: Organic | H6: No | I6: Free | J6: 0 | K6: 0 | L6: 0 | M6: 0 | N6: =IF(OR(NOT(OR(J6=0,J6=1)),NOT(OR(K6=0,K6=1)),NOT(OR(L6=0,L6=1)),NOT(OR(M6=0,M6=1)),NOT(OR(U6=0,U6=1))),"Yes","No") -> No | O6: =IF(OR(AND(M6=1,L6=0),AND(L6=1,K6=0),AND(K6=1,J6=0)),"Yes","No") -> No | P6: 0 | Q6: =IF(OR(AND(M6=0,P6>0),AND(M6=1,P6<=0)),"Yes","No") -> No | R6: =IF(AND(M6=1,P6>calc_helpers!$B$5),"Yes","No") -> No | S6: 0 | T6: =IF(S6>0,"Yes","No") -> No | U6: 0 | W6: =IF(OR(AND(M6=1,ISBLANK(V6)),AND(M6=0,NOT(ISBLANK(V6)))),"Yes","No") -> No | X6: 66.6 | Y6: No | Z6: =IF(M6=1,P6,"")
A7: USR-100006 | B7: 45685 | C7: Control | D7: East | E7: Mobile | F7: No | G7: Organic | H7: No | I7: Premium | J7: 1 | K7: 0 | L7: 0 | M7: 0 | N7: =IF(OR(NOT(OR(J7=0,J7=1)),NOT(OR(K7=0,K7=1)),NOT(OR(L7=0,L7=1)),NOT(OR(M7=0,M7=1)),NOT(OR(U7=0,U7=1))),"Yes","No") -> No | O7: =IF(OR(AND(M7=1,L7=0),AND(L7=1,K7=0),AND(K7=1,J7=0)),"Yes","No") -> No | P7: 0 | Q7: =IF(OR(AND(M7=0,P7>0),AND(M7=1,P7<=0)),"Yes","No") -> No | R7: =IF(AND(M7=1,P7>calc_helpers!$B$5),"Yes","No") -> No | S7: 0 | T7: =IF(S7>0,"Yes","No") -> No | U7: 0 | W7: =IF(OR(AND(M7=1,ISBLANK(V7)),AND(M7=0,NOT(ISBLANK(V7)))),"Yes","No") -> No | X7: 40.8 | Y7: No | Z7: =IF(M7=1,P7,"")
A8: USR-100007 | B8: 45755 | C8: Control | D8: East | E8: Mobile | F8: No | G8: Paid Search | H8: No | I8: Basic | J8: 1 | K8: 1 | L8: 0 | M8: 0 | N8: =IF(OR(NOT(OR(J8=0,J8=1)),NOT(OR(K8=0,K8=1)),NOT(OR(L8=0,L8=1)),NOT(OR(M8=0,M8=1)),NOT(OR(U8=0,U8=1))),"Yes","No") -> No | O8: =IF(OR(AND(M8=1,L8=0),AND(L8=1,K8=0),AND(K8=1,J8=0)),"Yes","No") -> No | P8: 0 | Q8: =IF(OR(AND(M8=0,P8>0),AND(M8=1,P8<=0)),"Yes","No") -> No | R8: =IF(AND(M8=1,P8>calc_helpers!$B$5),"Yes","No") -> No | S8: 0 | T8: =IF(S8>0,"Yes","No") -> No | U8: 0 | W8: =IF(OR(AND(M8=1,ISBLANK(V8)),AND(M8=0,NOT(ISBLANK(V8)))),"Yes","No") -> No | X8: 57.1 | Y8: No | Z8: =IF(M8=1,P8,"")
A9: USR-100008 | B9: 45794 | C9: Control | D9: South | E9: Mobile | F9: No | G9: Paid Search | H9: No | I9: Free | J9: 0 | K9: 0 | L9: 0 | M9: 0 | N9: =IF(OR(NOT(OR(J9=0,J9=1)),NOT(OR(K9=0,K9=1)),NOT(OR(L9=0,L9=1)),NOT(OR(M9=0,M9=1)),NOT(OR(U9=0,U9=1))),"Yes","No") -> No | O9: =IF(OR(AND(M9=1,L9=0),AND(L9=1,K9=0),AND(K9=1,J9=0)),"Yes","No") -> No | P9: 0 | Q9: =IF(OR(AND(M9=0,P9>0),AND(M9=1,P9<=0)),"Yes","No") -> No | R9: =IF(AND(M9=1,P9>calc_helpers!$B$5),"Yes","No") -> No | S9: 0 | T9: =IF(S9>0,"Yes","No") -> No | U9: 0 | W9: =IF(OR(AND(M9=1,ISBLANK(V9)),AND(M9=0,NOT(ISBLANK(V9)))),"Yes","No") -> No | X9: 36.4 | Y9: No | Z9: =IF(M9=1,P9,"")
A10: USR-100009 | B10: 45711 | C10: Control | D10: South | E10: Tablet | F10: No | G10: Referral | H10: No | I10: Basic | J10: 0 | K10: 0 | L10: 0 | M10: 0 | N10: =IF(OR(NOT(OR(J10=0,J10=1)),NOT(OR(K10=0,K10=1)),NOT(OR(L10=0,L10=1)),NOT(OR(M10=0,M10=1)),NOT(OR(U10=0,U10=1))),"Yes","No") -> No | O10: =IF(OR(AND(M10=1,L10=0),AND(L10=1,K10=0),AND(K10=1,J10=0)),"Yes","No") -> No | P10: 0 | Q10: =IF(OR(AND(M10=0,P10>0),AND(M10=1,P10<=0)),"Yes","No") -> No | R10: =IF(AND(M10=1,P10>calc_helpers!$B$5),"Yes","No") -> No | S10: 0 | T10: =IF(S10>0,"Yes","No") -> No | U10: 0 | W10: =IF(OR(AND(M10=1,ISBLANK(V10)),AND(M10=0,NOT(ISBLANK(V10)))),"Yes","No") -> No | X10: 55.4 | Y10: No | Z10: =IF(M10=1,P10,"")
A11: USR-100010 | B11: 45806 | C11: Control | D11: West | E11: Desktop | F11: No | G11: Social | H11: No | I11: Free | J11: 1 | K11: 0 | L11: 0 | M11: 0 | N11: =IF(OR(NOT(OR(J11=0,J11=1)),NOT(OR(K11=0,K11=1)),NOT(OR(L11=0,L11=1)),NOT(OR(M11=0,M11=1)),NOT(OR(U11=0,U11=1))),"Yes","No") -> No | O11: =IF(OR(AND(M11=1,L11=0),AND(L11=1,K11=0),AND(K11=1,J11=0)),"Yes","No") -> No | P11: 0 | Q11: =IF(OR(AND(M11=0,P11>0),AND(M11=1,P11<=0)),"Yes","No") -> No | R11: =IF(AND(M11=1,P11>calc_helpers!$B$5),"Yes","No") -> No | S11: 0 | T11: =IF(S11>0,"Yes","No") -> No | U11: 0 | W11: =IF(OR(AND(M11=1,ISBLANK(V11)),AND(M11=0,NOT(ISBLANK(V11)))),"Yes","No") -> No | X11: 57.3 | Y11: No | Z11: =IF(M11=1,P11,"")
A12: USR-100011 | B12: 45777 | C12: Control | D12: East | E12: Mobile | F12: No | G12: Paid Search | H12: No | I12: Basic | J12: 1 | K12: 1 | L12: 1 | M12: 0 | N12: =IF(OR(NOT(OR(J12=0,J12=1)),NOT(OR(K12=0,K12=1)),NOT(OR(L12=0,L12=1)),NOT(OR(M12=0,M12=1)),NOT(OR(U12=0,U12=1))),"Yes","No") -> No | O12: =IF(OR(AND(M12=1,L12=0),AND(L12=1,K12=0),AND(K12=1,J12=0)),"Yes","No") -> No | P12: 0 | Q12: =IF(OR(AND(M12=0,P12>0),AND(M12=1,P12<=0)),"Yes","No") -> No | R12: =IF(AND(M12=1,P12>calc_helpers!$B$5),"Yes","No") -> No | S12: 0 | T12: =IF(S12>0,"Yes","No") -> No | U12: 0 | W12: =IF(OR(AND(M12=1,ISBLANK(V12)),AND(M12=0,NOT(ISBLANK(V12)))),"Yes","No") -> No | X12: 63.6 | Y12: No | Z12: =IF(M12=1,P12,"")
A13: USR-100012 | B13: 45732 | C13: Control | D13: East | E13: Mobile | F13: No | G13: Social | H13: No | I13: Premium | J13: 1 | K13: 1 | L13: 1 | M13: 0 | N13: =IF(OR(NOT(OR(J13=0,J13=1)),NOT(OR(K13=0,K13=1)),NOT(OR(L13=0,L13=1)),NOT(OR(M13=0,M13=1)),NOT(OR(U13=0,U13=1))),"Yes","No") -> No | O13: =IF(OR(AND(M13=1,L13=0),AND(L13=1,K13=0),AND(K13=1,J13=0)),"Yes","No") -> No | P13: 0 | Q13: =IF(OR(AND(M13=0,P13>0),AND(M13=1,P13<=0)),"Yes","No") -> No | R13: =IF(AND(M13=1,P13>calc_helpers!$B$5),"Yes","No") -> No | S13: 1 | T13: =IF(S13>0,"Yes","No") -> Yes | U13: 0 | W13: =IF(OR(AND(M13=1,ISBLANK(V13)),AND(M13=0,NOT(ISBLANK(V13)))),"Yes","No") -> No | X13: 80.4 | Y13: No | Z13: =IF(M13=1,P13,"")
... A60: USR-100059 | B60: 45761 | C60: Control | D60: North | E60: Mobile | F60: No | G60: Social | H60: No | I60: Free | J60: 0 | K60: 0 | L60: 0 | M60: 0 | N60: =IF(OR(NOT(OR(J60=0,J60=1)),NOT(OR(K60=0,K60=1)),NOT(OR(L60=0,L60=1)),NOT(OR(M60=0,M60=1)),NOT(OR(U60=0,U60=1))),"Yes","No") -> No | O60: =IF(OR(AND(M60=1,L60=0),AND(L60=1,K60=0),AND(K60=1,J60=0)),"Yes","No") -> No | P60: 0 | Q60: =IF(OR(AND(M60=0,P60>0),AND(M60=1,P60<=0)),"Yes","No") -> No | R60: =IF(AND(M60=1,P60>calc_helpers!$B$5),"Yes","No") -> No | S60: 2 | T60: =IF(S60>0,"Yes","No") -> Yes | U60: 0 | W60: =IF(OR(AND(M60=1,ISBLANK(V60)),AND(M60=0,NOT(ISBLANK(V60)))),"Yes","No") -> No | X60: 48.9 | Y60: No | Z60: =IF(M60=1,P60,"")
A61: USR-100060 | B61: 45658 | C61: Control | D61: West | E61: Mobile | F61: No | G61: Social | H61: No | I61: Free | J61: 1 | K61: 1 | L61: 1 | M61: 1 | N61: =IF(OR(NOT(OR(J61=0,J61=1)),NOT(OR(K61=0,K61=1)),NOT(OR(L61=0,L61=1)),NOT(OR(M61=0,M61=1)),NOT(OR(U61=0,U61=1))),"Yes","No") -> No | O61: =IF(OR(AND(M61=1,L61=0),AND(L61=1,K61=0),AND(K61=1,J61=0)),"Yes","No") -> No | P61: 240.42 | Q61: =IF(OR(AND(M61=0,P61>0),AND(M61=1,P61<=0)),"Yes","No") -> No | R61: =IF(AND(M61=1,P61>calc_helpers!$B$5),"Yes","No") -> No | S61: 0 | T61: =IF(S61>0,"Yes","No") -> No | U61: 0 | V61: 16 | W61: =IF(OR(AND(M61=1,ISBLANK(V61)),AND(M61=0,NOT(ISBLANK(V61)))),"Yes","No") -> No | X61: 56.5 | Y61: No | Z61: =IF(M61=1,P61,"") -> 240.42
A62: USR-100061 | B62: 45749 | C62: Control | D62: South | E62: Mobile | F62: No | G62: Referral | H62: No | I62: Free | J62: 1 | K62: 0 | L62: 0 | M62: 0 | N62: =IF(OR(NOT(OR(J62=0,J62=1)),NOT(OR(K62=0,K62=1)),NOT(OR(L62=0,L62=1)),NOT(OR(M62=0,M62=1)),NOT(OR(U62=0,U62=1))),"Yes","No") -> No | O62: =IF(OR(AND(M62=1,L62=0),AND(L62=1,K62=0),AND(K62=1,J62=0)),"Yes","No") -> No | P62: 0 | Q62: =IF(OR(AND(M62=0,P62>0),AND(M62=1,P62<=0)),"Yes","No") -> No | R62: =IF(AND(M62=1,P62>calc_helpers!$B$5),"Yes","No") -> No | S62: 0 | T62: =IF(S62>0,"Yes","No") -> No | U62: 0 | W62: =IF(OR(AND(M62=1,ISBLANK(V62)),AND(M62=0,NOT(ISBLANK(V62)))),"Yes","No") -> No | X62: 53.7 | Y62: No | Z62: =IF(M62=1,P62,"")
A63: USR-100062 | B63: 45745 | C63: Control | D63: North | E63: Mobile | F63: No | G63: Social | H63: No | I63: Premium | J63: 0 | K63: 0 | L63: 0 | M63: 0 | N63: =IF(OR(NOT(OR(J63=0,J63=1)),NOT(OR(K63=0,K63=1)),NOT(OR(L63=0,L63=1)),NOT(OR(M63=0,M63=1)),NOT(OR(U63=0,U63=1))),"Yes","No") -> No | O63: =IF(OR(AND(M63=1,L63=0),AND(L63=1,K63=0),AND(K63=1,J63=0)),"Yes","No") -> No | P63: 0 | Q63: =IF(OR(AND(M63=0,P63>0),AND(M63=1,P63<=0)),"Yes","No") -> No | R63: =IF(AND(M63=1,P63>calc_helpers!$B$5),"Yes","No") -> No | S63: 0 | T63: =IF(S63>0,"Yes","No") -> No | U63: 0 | W63: =IF(OR(AND(M63=1,ISBLANK(V63)),AND(M63=0,NOT(ISBLANK(V63)))),"Yes","No") -> No | X63: 62.2 | Y63: No | Z63: =IF(M63=1,P63,"")
A64: USR-100063 | B64: 45792 | C64: Control | D64: South | E64: Desktop | F64: No | G64: Organic | H64: No | I64: Free | J64: 1 | K64: 0 | L64: 0 | M64: 0 | N64: =IF(OR(NOT(OR(J64=0,J64=1)),NOT(OR(K64=0,K64=1)),NOT(OR(L64=0,L64=1)),NOT(OR(M64=0,M64=1)),NOT(OR(U64=0,U64=1))),"Yes","No") -> No | O64: =IF(OR(AND(M64=1,L64=0),AND(L64=1,K64=0),AND(K64=1,J64=0)),"Yes","No") -> No | P64: 0 | Q64: =IF(OR(AND(M64=0,P64>0),AND(M64=1,P64<=0)),"Yes","No") -> No | R64: =IF(AND(M64=1,P64>calc_helpers!$B$5),"Yes","No") -> No | S64: 0 | T64: =IF(S64>0,"Yes","No") -> No | U64: 0 | W64: =IF(OR(AND(M64=1,ISBLANK(V64)),AND(M64=0,NOT(ISBLANK(V64)))),"Yes","No") -> No | X64: 50.2 | Y64: No | Z64: =IF(M64=1,P64,"")
A65: USR-100064 | B65: 45758 | C65: Control | D65: North | E65: Mobile | F65: No | G65: Organic | H65: No | I65: Basic | J65: 1 | K65: 0 | L65: 0 | M65: 0 | N65: =IF(OR(NOT(OR(J65=0,J65=1)),NOT(OR(K65=0,K65=1)),NOT(OR(L65=0,L65=1)),NOT(OR(M65=0,M65=1)),NOT(OR(U65=0,U65=1))),"Yes","No") -> No | O65: =IF(OR(AND(M65=1,L65=0),AND(L65=1,K65=0),AND(K65=1,J65=0)),"Yes","No") -> No | P65: 0 | Q65: =IF(OR(AND(M65=0,P65>0),AND(M65=1,P65<=0)),"Yes","No") -> No | R65: =IF(AND(M65=1,P65>calc_helpers!$B$5),"Yes","No") -> No | S65: 0 | T65: =IF(S65>0,"Yes","No") -> No | U65: 0 | W65: =IF(OR(AND(M65=1,ISBLANK(V65)),AND(M65=0,NOT(ISBLANK(V65)))),"Yes","No") -> No | X65: 74.3 | Y65: No | Z65: =IF(M65=1,P65,"")
A66: USR-100065 | B66: 45723 | C66: Control | D66: South | E66: Desktop | F66: No | G66: Paid Search | H66: No | I66: Free | J66: 1 | K66: 0 | L66: 0 | M66: 0 | N66: =IF(OR(NOT(OR(J66=0,J66=1)),NOT(OR(K66=0,K66=1)),NOT(OR(L66=0,L66=1)),NOT(OR(M66=0,M66=1)),NOT(OR(U66=0,U66=1))),"Yes","No") -> No | O66: =IF(OR(AND(M66=1,L66=0),AND(L66=1,K66=0),AND(K66=1,J66=0)),"Yes","No") -> No | P66: 0 | Q66: =IF(OR(AND(M66=0,P66>0),AND(M66=1,P66<=0)),"Yes","No") -> No | R66: =IF(AND(M66=1,P66>calc_helpers!$B$5),"Yes","No") -> No | S66: 0 | T66: =IF(S66>0,"Yes","No") -> No | U66: 0 | W66: =IF(OR(AND(M66=1,ISBLANK(V66)),AND(M66=0,NOT(ISBLANK(V66)))),"Yes","No") -> No | X66: 58 | Y66: No | Z66: =IF(M66=1,P66,"")
A67: USR-100066 | B67: 45807 | C67: Control | D67: South | E67: Mobile | F67: No | G67: Organic | H67: No | I67: Free | J67: 0 | K67: 0 | L67: 0 | M67: 0 | N67: =IF(OR(NOT(OR(J67=0,J67=1)),NOT(OR(K67=0,K67=1)),NOT(OR(L67=0,L67=1)),NOT(OR(M67=0,M67=1)),NOT(OR(U67=0,U67=1))),"Yes","No") -> No | O67: =IF(OR(AND(M67=1,L67=0),AND(L67=1,K67=0),AND(K67=1,J67=0)),"Yes","No") -> No | P67: 0 | Q67: =IF(OR(AND(M67=0,P67>0),AND(M67=1,P67<=0)),"Yes","No") -> No | R67: =IF(AND(M67=1,P67>calc_helpers!$B$5),"Yes","No") -> No | S67: 0 | T67: =IF(S67>0,"Yes","No") -> No | U67: 0 | W67: =IF(OR(AND(M67=1,ISBLANK(V67)),AND(M67=0,NOT(ISBLANK(V67)))),"Yes","No") -> No | X67: 46.7 | Y67: No | Z67: =IF(M67=1,P67,"")
A68: USR-100067 | B68: 45664 | C68: Control | D68: South | E68: Desktop | F68: No | G68: Organic | H68: No | I68: Premium | J68: 1 | K68: 0 | L68: 0 | M68: 0 | N68: =IF(OR(NOT(OR(J68=0,J68=1)),NOT(OR(K68=0,K68=1)),NOT(OR(L68=0,L68=1)),NOT(OR(M68=0,M68=1)),NOT(OR(U68=0,U68=1))),"Yes","No") -> No | O68: =IF(OR(AND(M68=1,L68=0),AND(L68=1,K68=0),AND(K68=1,J68=0)),"Yes","No") -> No | P68: 0 | Q68: =IF(OR(AND(M68=0,P68>0),AND(M68=1,P68<=0)),"Yes","No") -> No | R68: =IF(AND(M68=1,P68>calc_helpers!$B$5),"Yes","No") -> No | S68: 1 | T68: =IF(S68>0,"Yes","No") -> Yes | U68: 0 | W68: =IF(OR(AND(M68=1,ISBLANK(V68)),AND(M68=0,NOT(ISBLANK(V68)))),"Yes","No") -> No | X68: 49.6 | Y68: No | Z68: =IF(M68=1,P68,"")
A69: USR-100068 | B69: 45785 | C69: Control | D69: West | E69: Mobile | F69: No | G69: Social | H69: No | I69: Free | J69: 0 | K69: 0 | L69: 0 | M69: 0 | N69: =IF(OR(NOT(OR(J69=0,J69=1)),NOT(OR(K69=0,K69=1)),NOT(OR(L69=0,L69=1)),NOT(OR(M69=0,M69=1)),NOT(OR(U69=0,U69=1))),"Yes","No") -> No | O69: =IF(OR(AND(M69=1,L69=0),AND(L69=1,K69=0),AND(K69=1,J69=0)),"Yes","No") -> No | P69: 0 | Q69: =IF(OR(AND(M69=0,P69>0),AND(M69=1,P69<=0)),"Yes","No") -> No | R69: =IF(AND(M69=1,P69>calc_helpers!$B$5),"Yes","No") -> No | S69: 0 | T69: =IF(S69>0,"Yes","No") -> No | U69: 0 | W69: =IF(OR(AND(M69=1,ISBLANK(V69)),AND(M69=0,NOT(ISBLANK(V69)))),"Yes","No") -> No | X69: 60.4 | Y69: No | Z69: =IF(M69=1,P69,"")
A70: USR-100069 | B70: 45735 | C70: Control | D70: East | E70: Desktop | F70: No | G70: Email | H70: No | I70: Free | J70: 1 | K70: 1 | L70: 1 | M70: 0 | N70: =IF(OR(NOT(OR(J70=0,J70=1)),NOT(OR(K70=0,K70=1)),NOT(OR(L70=0,L70=1)),NOT(OR(M70=0,M70=1)),NOT(OR(U70=0,U70=1))),"Yes","No") -> No | O70: =IF(OR(AND(M70=1,L70=0),AND(L70=1,K70=0),AND(K70=1,J70=0)),"Yes","No") -> No | P70: 0 | Q70: =IF(OR(AND(M70=0,P70>0),AND(M70=1,P70<=0)),"Yes","No") -> No | R70: =IF(AND(M70=1,P70>calc_helpers!$B$5),"Yes","No") -> No | S70: 0 | T70: =IF(S70>0,"Yes","No") -> No | U70: 0 | W70: =IF(OR(AND(M70=1,ISBLANK(V70)),AND(M70=0,NOT(ISBLANK(V70)))),"Yes","No") -> No | X70: 55.3 | Y70: No | Z70: =IF(M70=1,P70,"")
A71: USR-100070 | B71: 45793 | C71: Control | D71: North | E71: Desktop | F71: No | G71: Organic | H71: No | I71: Free | J71: 0 | K71: 0 | L71: 0 | M71: 0 | N71: =IF(OR(NOT(OR(J71=0,J71=1)),NOT(OR(K71=0,K71=1)),NOT(OR(L71=0,L71=1)),NOT(OR(M71=0,M71=1)),NOT(OR(U71=0,U71=1))),"Yes","No") -> No | O71: =IF(OR(AND(M71=1,L71=0),AND(L71=1,K71=0),AND(K71=1,J71=0)),"Yes","No") -> No | P71: 0 | Q71: =IF(OR(AND(M71=0,P71>0),AND(M71=1,P71<=0)),"Yes","No") -> No | R71: =IF(AND(M71=1,P71>calc_helpers!$B$5),"Yes","No") -> No | S71: 0 | T71: =IF(S71>0,"Yes","No") -> No | U71: 0 | W71: =IF(OR(AND(M71=1,ISBLANK(V71)),AND(M71=0,NOT(ISBLANK(V71)))),"Yes","No") -> No | X71: 56.2 | Y71: No | Z71: =IF(M71=1,P71,"")
A72: USR-100071 | B72: 45724 | C72: Control | D72: West | E72: Mobile | F72: No | G72: Email | H72: No | I72: Free | J72: 0 | K72: 0 | L72: 0 | M72: 0 | N72: =IF(OR(NOT(OR(J72=0,J72=1)),NOT(OR(K72=0,K72=1)),NOT(OR(L72=0,L72=1)),NOT(OR(M72=0,M72=1)),NOT(OR(U72=0,U72=1))),"Yes","No") -> No | O72: =IF(OR(AND(M72=1,L72=0),AND(L72=1,K72=0),AND(K72=1,J72=0)),"Yes","No") -> No | P72: 0 | Q72: =IF(OR(AND(M72=0,P72>0),AND(M72=1,P72<=0)),"Yes","No") -> No | R72: =IF(AND(M72=1,P72>calc_helpers!$B$5),"Yes","No") -> No | S72: 0 | T72: =IF(S72>0,"Yes","No") -> No | U72: 0 | W72: =IF(OR(AND(M72=1,ISBLANK(V72)),AND(M72=0,NOT(ISBLANK(V72)))),"Yes","No") -> No | X72: 29.4 | Y72: No | Z72: =IF(M72=1,P72,"")
A73: USR-100072 | B73: 45724 | C73: Control | D73: East | E73: Mobile | F73: No | G73: Email | H73: No | I73: Free | J73: 1 | K73: 0 | L73: 0 | M73: 0 | N73: =IF(OR(NOT(OR(J73=0,J73=1)),NOT(OR(K73=0,K73=1)),NOT(OR(L73=0,L73=1)),NOT(OR(M73=0,M73=1)),NOT(OR(U73=0,U73=1))),"Yes","No") -> No | O73: =IF(OR(AND(M73=1,L73=0),AND(L73=1,K73=0),AND(K73=1,J73=0)),"Yes","No") -> No | P73: 0 | Q73: =IF(OR(AND(M73=0,P73>0),AND(M73=1,P73<=0)),"Yes","No") -> No | R73: =IF(AND(M73=1,P73>calc_helpers!$B$5),"Yes","No") -> No | S73: 0 | T73: =IF(S73>0,"Yes","No") -> No | U73: 0 | W73: =IF(OR(AND(M73=1,ISBLANK(V73)),AND(M73=0,NOT(ISBLANK(V73)))),"Yes","No") -> No | X73: 54.2 | Y73: No | Z73: =IF(M73=1,P73,"")
... A79: USR-100078 | B79: 45673 | C79: Control | D79: North | E79: Mobile | F79: No | G79: Organic | H79: No | I79: Free | J79: 0 | K79: 0 | L79: 0 | M79: 0 | N79: =IF(OR(NOT(OR(J79=0,J79=1)),NOT(OR(K79=0,K79=1)),NOT(OR(L79=0,L79=1)),NOT(OR(M79=0,M79=1)),NOT(OR(U79=0,U79=1))),"Yes","No") -> No | O79: =IF(OR(AND(M79=1,L79=0),AND(L79=1,K79=0),AND(K79=1,J79=0)),"Yes","No") -> No | P79: 0 | Q79: =IF(OR(AND(M79=0,P79>0),AND(M79=1,P79<=0)),"Yes","No") -> No | R79: =IF(AND(M79=1,P79>calc_helpers!$B$5),"Yes","No") -> No | S79: 2 | T79: =IF(S79>0,"Yes","No") -> Yes | U79: 0 | W79: =IF(OR(AND(M79=1,ISBLANK(V79)),AND(M79=0,NOT(ISBLANK(V79)))),"Yes","No") -> No | X79: 48.4 | Y79: No | Z79: =IF(M79=1,P79,"")
A80: USR-100079 | B80: 45708 | C80: Control | D80: West | E80: Desktop | F80: No | G80: Organic | H80: No | I80: Free | J80: 1 | K80: 1 | L80: 1 | M80: 1 | N80: =IF(OR(NOT(OR(J80=0,J80=1)),NOT(OR(K80=0,K80=1)),NOT(OR(L80=0,L80=1)),NOT(OR(M80=0,M80=1)),NOT(OR(U80=0,U80=1))),"Yes","No") -> No | O80: =IF(OR(AND(M80=1,L80=0),AND(L80=1,K80=0),AND(K80=1,J80=0)),"Yes","No") -> No | P80: 457.51 | Q80: =IF(OR(AND(M80=0,P80>0),AND(M80=1,P80<=0)),"Yes","No") -> No | R80: =IF(AND(M80=1,P80>calc_helpers!$B$5),"Yes","No") -> No | S80: 0 | T80: =IF(S80>0,"Yes","No") -> No | U80: 0 | V80: 7 | W80: =IF(OR(AND(M80=1,ISBLANK(V80)),AND(M80=0,NOT(ISBLANK(V80)))),"Yes","No") -> No | X80: 38 | Y80: No | Z80: =IF(M80=1,P80,"") -> 457.51
A81: USR-100080 | B81: 45798 | C81: Control | D81: East | E81: Mobile | F81: No | G81: Social | H81: No | I81: Free | J81: 1 | K81: 0 | L81: 0 | M81: 0 | N81: =IF(OR(NOT(OR(J81=0,J81=1)),NOT(OR(K81=0,K81=1)),NOT(OR(L81=0,L81=1)),NOT(OR(M81=0,M81=1)),NOT(OR(U81=0,U81=1))),"Yes","No") -> No | O81: =IF(OR(AND(M81=1,L81=0),AND(L81=1,K81=0),AND(K81=1,J81=0)),"Yes","No") -> No | P81: 0 | Q81: =IF(OR(AND(M81=0,P81>0),AND(M81=1,P81<=0)),"Yes","No") -> No | R81: =IF(AND(M81=1,P81>calc_helpers!$B$5),"Yes","No") -> No | S81: 0 | T81: =IF(S81>0,"Yes","No") -> No | U81: 0 | W81: =IF(OR(AND(M81=1,ISBLANK(V81)),AND(M81=0,NOT(ISBLANK(V81)))),"Yes","No") -> No | X81: 44.2 | Y81: No | Z81: =IF(M81=1,P81,"")
A82: USR-100081 | B82: 45785 | C82: Control | D82: South | E82: Mobile | F82: No | G82: Organic | H82: No | I82: Free | J82: 1 | K82: 1 | L82: 1 | M82: 0 | N82: =IF(OR(NOT(OR(J82=0,J82=1)),NOT(OR(K82=0,K82=1)),NOT(OR(L82=0,L82=1)),NOT(OR(M82=0,M82=1)),NOT(OR(U82=0,U82=1))),"Yes","No") -> No | O82: =IF(OR(AND(M82=1,L82=0),AND(L82=1,K82=0),AND(K82=1,J82=0)),"Yes","No") -> No | P82: 0 | Q82: =IF(OR(AND(M82=0,P82>0),AND(M82=1,P82<=0)),"Yes","No") -> No | R82: =IF(AND(M82=1,P82>calc_helpers!$B$5),"Yes","No") -> No | S82: 0 | T82: =IF(S82>0,"Yes","No") -> No | U82: 0 | W82: =IF(OR(AND(M82=1,ISBLANK(V82)),AND(M82=0,NOT(ISBLANK(V82)))),"Yes","No") -> No | X82: 81.2 | Y82: No | Z82: =IF(M82=1,P82,"")
A83: USR-100082 | B83: 45724 | C83: Control | D83: South | E83: Mobile | F83: No | G83: Referral | H83: No | I83: Free | J83: 1 | K83: 1 | L83: 0 | M83: 0 | N83: =IF(OR(NOT(OR(J83=0,J83=1)),NOT(OR(K83=0,K83=1)),NOT(OR(L83=0,L83=1)),NOT(OR(M83=0,M83=1)),NOT(OR(U83=0,U83=1))),"Yes","No") -> No | O83: =IF(OR(AND(M83=1,L83=0),AND(L83=1,K83=0),AND(K83=1,J83=0)),"Yes","No") -> No | P83: 0 | Q83: =IF(OR(AND(M83=0,P83>0),AND(M83=1,P83<=0)),"Yes","No") -> No | R83: =IF(AND(M83=1,P83>calc_helpers!$B$5),"Yes","No") -> No | S83: 0 | T83: =IF(S83>0,"Yes","No") -> No | U83: 0 | W83: =IF(OR(AND(M83=1,ISBLANK(V83)),AND(M83=0,NOT(ISBLANK(V83)))),"Yes","No") -> No | X83: 63.8 | Y83: No | Z83: =IF(M83=1,P83,"")
A84: USR-100083 | B84: 45748 | C84: Control | D84: South | E84: Desktop | F84: No | G84: Email | H84: No | I84: Free | J84: 0 | K84: 0 | L84: 0 | M84: 0 | N84: =IF(OR(NOT(OR(J84=0,J84=1)),NOT(OR(K84=0,K84=1)),NOT(OR(L84=0,L84=1)),NOT(OR(M84=0,M84=1)),NOT(OR(U84=0,U84=1))),"Yes","No") -> No | O84: =IF(OR(AND(M84=1,L84=0),AND(L84=1,K84=0),AND(K84=1,J84=0)),"Yes","No") -> No | P84: 0 | Q84: =IF(OR(AND(M84=0,P84>0),AND(M84=1,P84<=0)),"Yes","No") -> No | R84: =IF(AND(M84=1,P84>calc_helpers!$B$5),"Yes","No") -> No | S84: 0 | T84: =IF(S84>0,"Yes","No") -> No | U84: 0 | W84: =IF(OR(AND(M84=1,ISBLANK(V84)),AND(M84=0,NOT(ISBLANK(V84)))),"Yes","No") -> No | X84: 64.7 | Y84: No | Z84: =IF(M84=1,P84,"")
A85: USR-100084 | B85: 45719 | C85: Control | D85: West | E85: Mobile | F85: No | G85: Social | H85: No | I85: Basic | J85: 0 | K85: 0 | L85: 0 | M85: 0 | N85: =IF(OR(NOT(OR(J85=0,J85=1)),NOT(OR(K85=0,K85=1)),NOT(OR(L85=0,L85=1)),NOT(OR(M85=0,M85=1)),NOT(OR(U85=0,U85=1))),"Yes","No") -> No | O85: =IF(OR(AND(M85=1,L85=0),AND(L85=1,K85=0),AND(K85=1,J85=0)),"Yes","No") -> No | P85: 0 | Q85: =IF(OR(AND(M85=0,P85>0),AND(M85=1,P85<=0)),"Yes","No") -> No | R85: =IF(AND(M85=1,P85>calc_helpers!$B$5),"Yes","No") -> No | S85: 0 | T85: =IF(S85>0,"Yes","No") -> No | U85: 0 | W85: =IF(OR(AND(M85=1,ISBLANK(V85)),AND(M85=0,NOT(ISBLANK(V85)))),"Yes","No") -> No | X85: 60.4 | Y85: No | Z85: =IF(M85=1,P85,"")
A86: USR-100085 | B86: 45763 | C86: Control | D86: South | E86: Mobile | F86: No | G86: Paid Search | H86: No | I86: Free | J86: 0 | K86: 0 | L86: 0 | M86: 0 | N86: =IF(OR(NOT(OR(J86=0,J86=1)),NOT(OR(K86=0,K86=1)),NOT(OR(L86=0,L86=1)),NOT(OR(M86=0,M86=1)),NOT(OR(U86=0,U86=1))),"Yes","No") -> No | O86: =IF(OR(AND(M86=1,L86=0),AND(L86=1,K86=0),AND(K86=1,J86=0)),"Yes","No") -> No | P86: 0 | Q86: =IF(OR(AND(M86=0,P86>0),AND(M86=1,P86<=0)),"Yes","No") -> No | R86: =IF(AND(M86=1,P86>calc_helpers!$B$5),"Yes","No") -> No | S86: 0 | T86: =IF(S86>0,"Yes","No") -> No | U86: 0 | W86: =IF(OR(AND(M86=1,ISBLANK(V86)),AND(M86=0,NOT(ISBLANK(V86)))),"Yes","No") -> No | X86: 66.6 | Y86: No | Z86: =IF(M86=1,P86,"")
A87: USR-100086 | B87: 45666 | C87: Control | D87: North | E87: Desktop | F87: No | G87: Organic | H87: No | I87: Free | J87: 1 | K87: 0 | L87: 0 | M87: 0 | N87: =IF(OR(NOT(OR(J87=0,J87=1)),NOT(OR(K87=0,K87=1)),NOT(OR(L87=0,L87=1)),NOT(OR(M87=0,M87=1)),NOT(OR(U87=0,U87=1))),"Yes","No") -> No | O87: =IF(OR(AND(M87=1,L87=0),AND(L87=1,K87=0),AND(K87=1,J87=0)),"Yes","No") -> No | P87: 0 | Q87: =IF(OR(AND(M87=0,P87>0),AND(M87=1,P87<=0)),"Yes","No") -> No | R87: =IF(AND(M87=1,P87>calc_helpers!$B$5),"Yes","No") -> No | S87: 0 | T87: =IF(S87>0,"Yes","No") -> No | U87: 0 | W87: =IF(OR(AND(M87=1,ISBLANK(V87)),AND(M87=0,NOT(ISBLANK(V87)))),"Yes","No") -> No | X87: 50.9 | Y87: No | Z87: =IF(M87=1,P87,"")
A88: USR-100087 | B88: 45679 | C88: Control | D88: West | E88: Desktop | F88: No | G88: Social | H88: No | I88: Basic | J88: 0 | K88: 0 | L88: 0 | M88: 0 | N88: =IF(OR(NOT(OR(J88=0,J88=1)),NOT(OR(K88=0,K88=1)),NOT(OR(L88=0,L88=1)),NOT(OR(M88=0,M88=1)),NOT(OR(U88=0,U88=1))),"Yes","No") -> No | O88: =IF(OR(AND(M88=1,L88=0),AND(L88=1,K88=0),AND(K88=1,J88=0)),"Yes","No") -> No | P88: 0 | Q88: =IF(OR(AND(M88=0,P88>0),AND(M88=1,P88<=0)),"Yes","No") -> No | R88: =IF(AND(M88=1,P88>calc_helpers!$B$5),"Yes","No") -> No | S88: 0 | T88: =IF(S88>0,"Yes","No") -> No | U88: 0 | W88: =IF(OR(AND(M88=1,ISBLANK(V88)),AND(M88=0,NOT(ISBLANK(V88)))),"Yes","No") -> No | X88: 51 | Y88: No | Z88: =IF(M88=1,P88,"")
A89: USR-100088 | B89: 45777 | C89: Control | D89: South | E89: Mobile | F89: No | G89: Email | H89: No | I89: Premium | J89: 0 | K89: 0 | L89: 0 | M89: 0 | N89: =IF(OR(NOT(OR(J89=0,J89=1)),NOT(OR(K89=0,K89=1)),NOT(OR(L89=0,L89=1)),NOT(OR(M89=0,M89=1)),NOT(OR(U89=0,U89=1))),"Yes","No") -> No | O89: =IF(OR(AND(M89=1,L89=0),AND(L89=1,K89=0),AND(K89=1,J89=0)),"Yes","No") -> No | P89: 0 | Q89: =IF(OR(AND(M89=0,P89>0),AND(M89=1,P89<=0)),"Yes","No") -> No | R89: =IF(AND(M89=1,P89>calc_helpers!$B$5),"Yes","No") -> No | S89: 0 | T89: =IF(S89>0,"Yes","No") -> No | U89: 0 | W89: =IF(OR(AND(M89=1,ISBLANK(V89)),AND(M89=0,NOT(ISBLANK(V89)))),"Yes","No") -> No | X89: 65.8 | Y89: No | Z89: =IF(M89=1,P89,"")
A90: USR-100089 | B90: 45772 | C90: Control | D90: North | E90: Mobile | F90: No | G90: Referral | H90: No | I90: Basic | J90: 1 | K90: 0 | L90: 0 | M90: 0 | N90: =IF(OR(NOT(OR(J90=0,J90=1)),NOT(OR(K90=0,K90=1)),NOT(OR(L90=0,L90=1)),NOT(OR(M90=0,M90=1)),NOT(OR(U90=0,U90=1))),"Yes","No") -> No | O90: =IF(OR(AND(M90=1,L90=0),AND(L90=1,K90=0),AND(K90=1,J90=0)),"Yes","No") -> No | P90: 0 | Q90: =IF(OR(AND(M90=0,P90>0),AND(M90=1,P90<=0)),"Yes","No") -> No | R90: =IF(AND(M90=1,P90>calc_helpers!$B$5),"Yes","No") -> No | S90: 0 | T90: =IF(S90>0,"Yes","No") -> No | U90: 0 | W90: =IF(OR(AND(M90=1,ISBLANK(V90)),AND(M90=0,NOT(ISBLANK(V90)))),"Yes","No") -> No | X90: 61.8 | Y90: No | Z90: =IF(M90=1,P90,"")
A91: USR-100090 | B91: 45689 | C91: Control | D91: North | E91: Mobile | F91: No | G91: Organic | H91: No | I91: Basic | J91: 1 | K91: 0 | L91: 0 | M91: 0 | N91: =IF(OR(NOT(OR(J91=0,J91=1)),NOT(OR(K91=0,K91=1)),NOT(OR(L91=0,L91=1)),NOT(OR(M91=0,M91=1)),NOT(OR(U91=0,U91=1))),"Yes","No") -> No | O91: =IF(OR(AND(M91=1,L91=0),AND(L91=1,K91=0),AND(K91=1,J91=0)),"Yes","No") -> No | P91: 0 | Q91: =IF(OR(AND(M91=0,P91>0),AND(M91=1,P91<=0)),"Yes","No") -> No | R91: =IF(AND(M91=1,P91>calc_helpers!$B$5),"Yes","No") -> No | S91: 0 | T91: =IF(S91>0,"Yes","No") -> No | U91: 0 | W91: =IF(OR(AND(M91=1,ISBLANK(V91)),AND(M91=0,NOT(ISBLANK(V91)))),"Yes","No") -> No | X91: 54.5 | Y91: No | Z91: =IF(M91=1,P91,"")
...

Sheet calc_helpers
A1: Revenue outlier bound (converted users only, IQR method)
A2: Q1 (25th pct, converted revenue) | B2: =QUARTILE(experiment_data_clean!Z2:Z1401,1) -> 404.02
A3: Q3 (75th pct, converted revenue) | B3: =QUARTILE(experiment_data_clean!Z2:Z1401,3) -> 1178.665
A4: IQR | B4: =B3-B2 -> 774.645
A5: Upper bound (Q3 + 1.5*IQR) | B5: =B3+1.5*B4 -> 2340.6325

Sheet data_quality_checks
A1: Check | B1: Result | C1: Action Taken
A2: Raw row count | B2: 1408
A3: Exact duplicate rows found (full-row duplicates) | B3: 8 | C3: Removed, kept first occurrence
A4: Rows after deduplication | B4: 1400
A5: Remaining duplicate user_ids with conflicting data | B5: 0 | C5: None found — no manual review needed
A6: Missing device_type | B6: 18 | C6: Filled "Unknown", flagged device_type_filled_flag
A7: Missing traffic_source | B7: 24 | C7: Filled "Unknown", flagged traffic_source_filled_flag
A8: Missing engagement_score | B8: 14 | C8: Left blank, flagged engagement_score_missing_flag, excluded from average calculations (not imputed, to avoid biasing the metric)
A9: Invalid binary values (not 0/1) across all 5 binary columns | B9: 0 | C9: None found — confirmed via invalid_binary_flag, all values clean
A10: Funnel-logic inconsistencies (e.g. converted but never onboarded) | B10: 0 | C10: None found — funnel data is internally consistent
A11: Revenue/conversion logic mismatches | B11: 0 | C11: None found — revenue is 0 exactly when not converted, >0 exactly when converted
A12: days_to_convert logic mismatches | B12: 0 | C12: None found — populated only for converted users, as expected
A13: Revenue outliers among converted users (IQR method) | B13: 4 | C13: Flagged (not removed) — reviewed separately as part of guardrail / revenue-quality analysis
A14: Group counts after cleaning | B14: Control 690 / Treatment 710 | C14: Reasonably balanced, no group-size concern
A15: Segment distribution across groups (region/device/traffic/plan) | B15: Balanced | C15: See experiment_summary.xlsx segment sheets — no major skew that would suggest broken randomization
